```python
tunnel 1 mm-tunnelclient $MAHIMAHI_BASE 43198 100.64.0.4 100.64.0.3 --ingress-log=/home/pokorie/Documents/repos/pantheon/tmp/cubic_acklink_run1_flow1_uid217de1a9-c8db-47c2-a4c2-5a13efc5db94.log.ingress --egress-log=/home/pokorie/Documents/repos/pantheon/tmp/cubic_datalink_run1_flow1_uid217de1a9-c8db-47c2-a4c2-5a13efc5db94.log.egress

tunnel 1 mm-tunnelclient localhost 43198 100.64.0.4 100.64.0.3 --ingress-log=/home/pokorie/Documents/repos/pantheon/tmp/cubic_acklink_run1_flow1_uid217de1a9-c8db-47c2-a4c2-5a13efc5db94.log.ingress --egress-log=/home/pokorie/Documents/repos/pantheon/tmp/cubic_datalink_run1_flow1_uid217de1a9-c8db-47c2-a4c2-5a13efc5db94.log.egress

Traceback (most recent call last):
  File "/home/pokorie/Documents/repos/pantheon/src/wrappers/copa.py", line 46, in <module>
    main('do_ss:auto:0.1')
  File "/home/pokorie/Documents/repos/pantheon/src/wrappers/copa.py", line 29, in main
    check_call(cmd)
  File "/usr/lib/python2.7/subprocess.py", line 185, in check_call
    retcode = call(*popenargs, **kwargs)
  File "/usr/lib/python2.7/subprocess.py", line 172, in call
    return Popen(*popenargs, **kwargs).wait()
  File "/usr/lib/python2.7/subprocess.py", line 394, in __init__
    errread, errwrite)
  File "/usr/lib/python2.7/subprocess.py", line 1047, in _execute_child
    raise child_exception
OSError: [Errno 2] No such file or directory

Traceback (most recent call last):
  File "/home/pokorie/Documents/repos/pantheon/src/wrappers/verus.py", line 42, in <module>
    main()
  File "/home/pokorie/Documents/repos/pantheon/src/wrappers/verus.py", line 32, in main
    check_call(cmd, cwd=utils.tmp_dir)
  File "/usr/lib/python2.7/subprocess.py", line 185, in check_call
    retcode = call(*popenargs, **kwargs)
  File "/usr/lib/python2.7/subprocess.py", line 172, in call
    return Popen(*popenargs, **kwargs).wait()
  File "/usr/lib/python2.7/subprocess.py", line 394, in __init__
    errread, errwrite)
  File "/usr/lib/python2.7/subprocess.py", line 1047, in _execute_child
    raise child_exception
OSError: [Errno 2] No such file or directory

Traceback (most recent call last):
  File "/home/pokorie/Documents/repos/pantheon/src/wrappers/verus.py", line 42, in <module>
    main()
  File "/home/pokorie/Documents/repos/pantheon/src/wrappers/verus.py", line 37, in main
    check_call(cmd, cwd=utils.tmp_dir)
  File "/usr/lib/python2.7/subprocess.py", line 185, in check_call
    retcode = call(*popenargs, **kwargs)
  File "/usr/lib/python2.7/subprocess.py", line 172, in call
    return Popen(*popenargs, **kwargs).wait()
  File "/usr/lib/python2.7/subprocess.py", line 394, in __init__
    errread, errwrite)
  File "/usr/lib/python2.7/subprocess.py", line 1047, in _execute_child
    raise child_exception
OSError: [Errno 2] No such file or directory

Traceback (most recent call last):
  File "/home/pokorie/Documents/repos/pantheon/src/wrappers/sprout.py", line 46, in <module>
    main()
  File "/home/pokorie/Documents/repos/pantheon/src/wrappers/sprout.py", line 41, in main
    check_call(cmd)
  File "/usr/lib/python2.7/subprocess.py", line 185, in check_call
    retcode = call(*popenargs, **kwargs)
  File "/usr/lib/python2.7/subprocess.py", line 172, in call
    return Popen(*popenargs, **kwargs).wait()
  File "/usr/lib/python2.7/subprocess.py", line 394, in __init__
    errread, errwrite)
  File "/usr/lib/python2.7/subprocess.py", line 1047, in _execute_child
    raise child_exception
OSError: [Errno 2] No such file or directory

[tsm] tunnel 1 python /home/pokorie/Documents/repos/pantheon/src/wrappers/bbr.py receiver 38189
Attempt to set 'bbr' congestion control failed: No such file or directory
[tcm] tunnel 1 python /home/pokorie/Documents/repos/pantheon/src/wrappers/bbr.py sender 100.64.0.3 38189
Attempt to set 'bbr' congestion control failed: No such file or directory

Traceback (most recent call last):
  File "/home/pokorie/Documents/repos/pantheon/src/wrappers/taova.py", line 42, in <module>
    main()
  File "/home/pokorie/Documents/repos/pantheon/src/wrappers/taova.py", line 28, in main
    check_call(cmd)
  File "/usr/lib/python2.7/subprocess.py", line 185, in check_call
    retcode = call(*popenargs, **kwargs)
  File "/usr/lib/python2.7/subprocess.py", line 172, in call
    return Popen(*popenargs, **kwargs).wait()
  File "/usr/lib/python2.7/subprocess.py", line 394, in __init__
    errread, errwrite)
  File "/usr/lib/python2.7/subprocess.py", line 1047, in _execute_child
    raise child_exception
OSError: [Errno 2] No such file or directory
[tcm] tunnel 1 python /home/pokorie/Documents/repos/pantheon/src/wrappers/taova.py sender 100.64.0.3 36501
/bin/sh: 1: /home/pokorie/Documents/repos/pantheon/third_party/genericCC/sender: not found
Traceback (most recent call last):
  File "/home/pokorie/Documents/repos/pantheon/src/wrappers/taova.py", line 42, in <module>
    main()
  File "/home/pokorie/Documents/repos/pantheon/src/wrappers/taova.py", line 37, in main
    check_call(sh_cmd, shell=True)
  File "/usr/lib/python2.7/subprocess.py", line 190, in check_call
    raise CalledProcessError(retcode, cmd)
subprocess.CalledProcessError: Command 'export MIN_RTT=1000000 && /home/pokorie/Documents/repos/pantheon/third_party/genericCC/sender serverip=100.64.0.3 serverport=36501 if=/home/pokorie/Documents/repos/pantheon/third_party/genericCC/RemyCC-2014-100x.dna offduration=1 onduration=1000000 traffic_params=deterministic,num_cycles=1' returned non-zero exit status 127

[tcm] tunnel 1 python /home/pokorie/Documents/repos/pantheon/src/wrappers/quic.py sender 40839
Traceback (most recent call last):
  File "/home/pokorie/Documents/repos/pantheon/src/wrappers/quic.py", line 123, in <module>
    main()
  File "/home/pokorie/Documents/repos/pantheon/src/wrappers/quic.py", line 106, in main
    check_call(cmd)
  File "/usr/lib/python2.7/subprocess.py", line 185, in check_call
    retcode = call(*popenargs, **kwargs)
  File "/usr/lib/python2.7/subprocess.py", line 172, in call
    return Popen(*popenargs, **kwargs).wait()
  File "/usr/lib/python2.7/subprocess.py", line 394, in __init__
    errread, errwrite)
  File "/usr/lib/python2.7/subprocess.py", line 1047, in _execute_child
    raise child_exception
OSError: [Errno 2] No such file or directory
[tsm] tunnel 1 python /home/pokorie/Documents/repos/pantheon/src/wrappers/quic.py receiver 100.64.0.4 40839
Traceback (most recent call last):
  File "/home/pokorie/Documents/repos/pantheon/src/wrappers/quic.py", line 123, in <module>
    main()
  File "/home/pokorie/Documents/repos/pantheon/src/wrappers/quic.py", line 116, in main
    if call(cmd, stdout=devnull) == 0:
  File "/usr/lib/python2.7/subprocess.py", line 172, in call
    return Popen(*popenargs, **kwargs).wait()
  File "/usr/lib/python2.7/subprocess.py", line 394, in __init__
    errread, errwrite)
  File "/usr/lib/python2.7/subprocess.py", line 1047, in _execute_child
    raise child_exception
OSError: [Errno 2] No such file or directory


[tsm] tunnel 1 python /home/pokorie/Documents/repos/pantheon/src/wrappers/pcc.py receiver 32795
Traceback (most recent call last):
  File "/home/pokorie/Documents/repos/pantheon/src/wrappers/pcc.py", line 45, in <module>
    main()
  File "/home/pokorie/Documents/repos/pantheon/src/wrappers/pcc.py", line 32, in main
    check_call(cmd)
  File "/usr/lib/python2.7/subprocess.py", line 185, in check_call
    retcode = call(*popenargs, **kwargs)
  File "/usr/lib/python2.7/subprocess.py", line 172, in call
    return Popen(*popenargs, **kwargs).wait()
  File "/usr/lib/python2.7/subprocess.py", line 394, in __init__
    errread, errwrite)
  File "/usr/lib/python2.7/subprocess.py", line 1047, in _execute_child
    raise child_exception
OSError: [Errno 2] No such file or directory
[tcm] tunnel 1 python /home/pokorie/Documents/repos/pantheon/src/wrappers/pcc.py sender 100.64.0.3 32795
Traceback (most recent call last):
  File "/home/pokorie/Documents/repos/pantheon/src/wrappers/pcc.py", line 45, in <module>
    main()
  File "/home/pokorie/Documents/repos/pantheon/src/wrappers/pcc.py", line 40, in main
    check_call(cmd, stderr=devnull)
  File "/usr/lib/python2.7/subprocess.py", line 185, in check_call
    retcode = call(*popenargs, **kwargs)
  File "/usr/lib/python2.7/subprocess.py", line 172, in call
    return Popen(*popenargs, **kwargs).wait()
  File "/usr/lib/python2.7/subprocess.py", line 394, in __init__
    errread, errwrite)
  File "/usr/lib/python2.7/subprocess.py", line 1047, in _execute_child
    raise child_exception
OSError: [Errno 2] No such file or directory

[tcm] tunnel 1 python /home/pokorie/Documents/repos/pantheon/src/wrappers/webrtc.py sender 36197
Traceback (most recent call last):
  File "/home/pokorie/Documents/repos/pantheon/src/wrappers/webrtc.py", line 93, in <module>
    main()
  File "/home/pokorie/Documents/repos/pantheon/src/wrappers/webrtc.py", line 54, in main
    xvfb_proc = Popen(['Xvfb', ':1'])
  File "/usr/lib/python2.7/subprocess.py", line 394, in __init__
    errread, errwrite)
  File "/usr/lib/python2.7/subprocess.py", line 1047, in _execute_child
    raise child_exception
OSError: [Errno 2] No such file or directory
[tsm] tunnel 1 python /home/pokorie/Documents/repos/pantheon/src/wrappers/webrtc.py receiver 100.64.0.4 36197
Traceback (most recent call last):
  File "/home/pokorie/Documents/repos/pantheon/src/wrappers/webrtc.py", line 93, in <module>
    main()
  File "/home/pokorie/Documents/repos/pantheon/src/wrappers/webrtc.py", line 77, in main
    xvfb_proc = Popen(['Xvfb', ':2'])
  File "/usr/lib/python2.7/subprocess.py", line 394, in __init__
    errread, errwrite)
  File "/usr/lib/python2.7/subprocess.py", line 1047, in _execute_child
    raise child_exception
OSError: [Errno 2] No such file or directory


[tsm] tunnel 1 python /home/pokorie/Documents/repos/pantheon/src/wrappers/ledbat.py receiver 43089
Traceback (most recent call last):
  File "/home/pokorie/Documents/repos/pantheon/src/wrappers/ledbat.py", line 47, in <module>
    main()
  File "/home/pokorie/Documents/repos/pantheon/src/wrappers/ledbat.py", line 26, in main
    check_call(cmd, stdout=devnull)
  File "/usr/lib/python2.7/subprocess.py", line 185, in check_call
    retcode = call(*popenargs, **kwargs)
  File "/usr/lib/python2.7/subprocess.py", line 172, in call
    return Popen(*popenargs, **kwargs).wait()
  File "/usr/lib/python2.7/subprocess.py", line 394, in __init__
    errread, errwrite)
  File "/usr/lib/python2.7/subprocess.py", line 1047, in _execute_child
    raise child_exception
OSError: [Errno 2] No such file or directory
[tcm] tunnel 1 python /home/pokorie/Documents/repos/pantheon/src/wrappers/ledbat.py sender 100.64.0.3 43089
Traceback (most recent call last):
  File "/home/pokorie/Documents/repos/pantheon/src/wrappers/ledbat.py", line 47, in <module>
    main()
  File "/home/pokorie/Documents/repos/pantheon/src/wrappers/ledbat.py", line 31, in main
    proc = Popen(cmd, stdin=PIPE)
  File "/usr/lib/python2.7/subprocess.py", line 394, in __init__
    errread, errwrite)
  File "/usr/lib/python2.7/subprocess.py", line 1047, in _execute_child
    raise child_exception
OSError: [Errno 2] No such file or directory


Traceback (most recent call last):
  File "/home/pokorie/Documents/repos/pantheon/src/wrappers/pcc_experimental.py", line 39, in <module>
    main()
  File "/home/pokorie/Documents/repos/pantheon/src/wrappers/pcc_experimental.py", line 28, in main
    check_call(cmd)
  File "/usr/lib/python2.7/subprocess.py", line 185, in check_call
    retcode = call(*popenargs, **kwargs)
  File "/usr/lib/python2.7/subprocess.py", line 172, in call
    return Popen(*popenargs, **kwargs).wait()
  File "/usr/lib/python2.7/subprocess.py", line 394, in __init__
    errread, errwrite)
  File "/usr/lib/python2.7/subprocess.py", line 1047, in _execute_child
    raise child_exception
OSError: [Errno 2] No such file or directory
[tcm] tunnel 1 python /home/pokorie/Documents/repos/pantheon/src/wrappers/pcc_experimental.py sender 100.64.0.3 33089
Traceback (most recent call last):
  File "/home/pokorie/Documents/repos/pantheon/src/wrappers/pcc_experimental.py", line 39, in <module>
    main()
  File "/home/pokorie/Documents/repos/pantheon/src/wrappers/pcc_experimental.py", line 34, in main
    check_call(cmd)
  File "/usr/lib/python2.7/subprocess.py", line 185, in check_call
    retcode = call(*popenargs, **kwargs)
  File "/usr/lib/python2.7/subprocess.py", line 172, in call
    return Popen(*popenargs, **kwargs).wait()
  File "/usr/lib/python2.7/subprocess.py", line 394, in __init__
    errread, errwrite)
  File "/usr/lib/python2.7/subprocess.py", line 1047, in _execute_child
    raise child_exception
OSError: [Errno 2] No such file or directory


No performance data for scheme copa
No performance data for scheme quic
No performance data for scheme sprout
No performance data for scheme vegas
No performance data for scheme bbr
No performance data for scheme verus
No performance data for scheme pcc
No performance data for scheme pcc_experimental
No performance data for scheme webrtc
No performance data for scheme taova
No performance data for scheme ledbat


Traceback (most recent call last):
  File "/home/pokorie/Documents/repos/pantheon/src/analysis/report.py", line 344, in <module>
    main()
  File "/home/pokorie/Documents/repos/pantheon/src/analysis/report.py", line 340, in main
    Report(args).run()
  File "/home/pokorie/Documents/repos/pantheon/src/analysis/report.py", line 328, in run
    check_call(cmd, cwd=utils.tmp_dir)
  File "/home/pokorie/Documents/repos/pantheon/src/helpers/subprocess_wrappers.py", line 24, in check_call
    return subprocess.check_call(cmd, **kwargs)
  File "/usr/lib/python2.7/subprocess.py", line 185, in check_call
    retcode = call(*popenargs, **kwargs)
  File "/usr/lib/python2.7/subprocess.py", line 172, in call
    return Popen(*popenargs, **kwargs).wait()
  File "/usr/lib/python2.7/subprocess.py", line 394, in __init__
    errread, errwrite)
  File "/usr/lib/python2.7/subprocess.py", line 1047, in _execute_child
    raise child_exception
OSError: [Errno 2] No such file or directory
Traceback (most recent call last):
  File "src/analysis/analyze.py", line 33, in <module>
    main()
  File "src/analysis/analyze.py", line 29, in main
    check_call(report_cmd)
  File "/home/pokorie/Documents/repos/pantheon/src/helpers/subprocess_wrappers.py", line 24, in check_call
    return subprocess.check_call(cmd, **kwargs)
  File "/usr/lib/python2.7/subprocess.py", line 190, in check_call
    raise CalledProcessError(retcode, cmd)
subprocess.CalledProcessError: Command '['python', '/home/pokorie/Documents/repos/pantheon/src/analysis/report.py', '--data-dir', '/home/pokorie/Documents/repos/pantheon/src/experiments/data']' returned non-zero exit status 1
```